Workbook

Sheet คำอธิบาย
A1: Siam Legends Online — ตารางสมดุลเกม (มอน / เลเวล / EXP)
A3: วิธีใช้
A4: 1. แก้เฉพาะช่องตัวอักษรสีน้ำเงินในชีต 'ตั้งค่า' และในชีต 'มอน' (เลเวล ประเภท นิสัย ตัวคูณ) ช่องพื้นเหลืองคือค่าสำคัญ
A5: 2. ตัวเลขสีดำทั้งหมดเป็นสูตร จะคำนวณใหม่เองเมื่อแก้ค่าในชีต 'ตั้งค่า' ห้ามพิมพ์ทับ
A6: 3. ดูผลลัพธ์ที่ท้ายชีต 'ตั้งค่า' (เวลาเล่นถึงเลเวล 10 / 20 / 30 / 50 / สูงสุด) แล้วปรับจนพอใจ
A7: 4. เพิ่มมอนใหม่: คัดลอกแถวในชีต 'มอน' แล้วแก้ชื่อ แมพ เลเวล — ค่าพลังจะคำนวณให้เอง
A9: หลักการคำนวณ
A10: • มอนเลเวล L ถูกออกแบบให้ผู้เล่นเลเวล L (ยังไม่รวมสกิล) ตีจำนวน 'ตีกี่ทีตาย' ครั้ง
A11: • เวลาเป้าหมายต่อเลเวล = a × เลเวล^k + เวลาขั้นต่ำ โดย a ถูกคำนวณให้เวลารวมถึงเลเวลสูงสุดเท่ากับ 'ชั่วโมงเล่นถึงเลเวลสูงสุด'
A12: • EXP มอน = EXP ที่ต้องใช้ ÷ จำนวนตัวที่ควรฆ่าในเวลาเป้าหมาย
A13: • 'เวลาจริง' ใช้ EXP มอนที่ปัดเศษแล้ว จึงอาจต่างจากเป้าหมายเล็กน้อย
A14: • เวลาต่อการฆ่า = ตีกี่ทีตาย × ความเร็วโจมตี + เวลาเดินหาเป้าหมาย (ประเมินแบบเล่นคนเดียว ตีมอนเลเวลเท่ากัน)
... A19: • ชื่อมอนและแมพเป็นร่างแรก แก้ได้ตามใจ

Sheet ตั้งค่า
B1: ตั้งค่าเป้าหมายและตัวเลขพื้นฐาน
B2: แก้เฉพาะช่องสีน้ำเงิน · พื้นเหลือง = ค่าสำคัญที่ควรลองปรับก่อน
B4: ค่า | C4: ตัวเลข | D4: หน่วย | E4: คำอธิบาย
B5: เป้าหมายเวลาเล่น
B6: เลเวลสูงสุด | C6: 100 | D6: เลเวล | E6: ตารางรองรับถึง 100
B7: ชั่วโมงเล่นถึงเลเวลสูงสุด | C7: 400 | D7: ชั่วโมง | E7: เล่นคนเดียว ไม่รวมสกิล/ปาร์ตี้/โบนัส
B8: ความชันเส้นเวลา (k) | C8: 2 | E8: ยิ่งมาก = ช่วงต้นเร็ว ช่วงปลายช้า
B9: เวลาขั้นต่ำต่อเลเวล | C9: 0.6 | D9: นาที | E9: ทำให้เลเวลแรก ๆ ไม่เร็วเกินไป
B10: ค่า a (ตัวช่วยคำนวณ) | C10: =(C7*60-C9*(C6-1))/SUMPRODUCT((เลเวล!$A$5:$A$104<C6)*(เลเวล!$A$5:$A$104^C8)) -> 0.072911832 | E10: ห้ามแก้ — ปรับให้เวลารวมตรงเป้า
B11: ผู้เล่น (ค่าพื้นฐาน ยังไม่รวมสกิล)
B12: พลังโจมตีตั้งต้น | C12: 10 | E12: ตรงกับเกมตอนนี้: 10 + 2 × เลเวล
B13: พลังโจมตีเพิ่มต่อเลเวล | C13: 2
B14: อุปกรณ์เพิ่มพลังโจมตีต่อเลเวล | C14: 0.02 | E14: สะท้อนว่าผู้เล่นได้อาวุธดีขึ้นเรื่อย ๆ
B15: HP ตั้งต้น | C15: 90 | E15: ตรงกับเกมตอนนี้: 90 + 10 × เลเวล
B16: HP เพิ่มต่อเลเวล | C16: 10
B17: อุปกรณ์เพิ่ม HP ต่อเลเวล | C17: 0.015
B18: ความเร็วโจมตี | C18: 0.7 | D18: วินาที/ที | E18: ตรงกับ PLAYER_ASPD_MS ในเกม
B19: มอนปกติ (เทียบกับผู้เล่นเลเวลเท่ากัน)
B20: ตีกี่ทีตาย | C20: 4 | D20: ที | E20: ความรู้สึกหลักของการตีมอน
B21: เวลาเดินหาเป้าหมายต่อตัว | C21: 4 | D21: วินาที | E21: รวมเวลาเดินและรอมอนเกิด
B22: พลังป้องกันมอน | C22: 0.05 | D22: ของพลังโจมตีผู้เล่น
B23: มอนตีกี่ทีผู้เล่นตาย | C23: 12 | D23: ที | E23: ใช้เมื่อเปิดระบบมอนตีกลับ
B24: EXP ที่ต้องใช้: ค่าตั้งต้น | C24: 15 | E24: EXP ขึ้นเลเวล = ค่าตั้งต้น × เลเวล^เลขชี้กำลัง
B25: EXP ที่ต้องใช้: เลขชี้กำลัง | C25: 3 | E25: ยิ่งมาก EXP ต่อมอนช่วงปลายยิ่งสูง
B26: เบี้ยต่อ EXP | C26: 0.5 | D26: เบี้ย | E26: เงินในเกม (ตั้งชื่อชั่วคราวว่า เบี้ย)
B27: เบี้ยสุ่ม ± | C27: 0.2
B28: บอส (ตัวคูณจากมอนปกติเลเวลเดียวกัน)
B29: ตัวคูณ HP | C29: 40 | D29: เท่า | E29: ตั้งใจให้ต้องใช้ปาร์ตี้หรือยา
B30: ตัวคูณ EXP | C30: 25 | D30: เท่า
B31: ตัวคูณพลังโจมตี | C31: 2.5 | D31: เท่า
B32: ตัวคูณพลังป้องกัน | C32: 2 | D32: เท่า
B33: ตัวคูณเบี้ย | C33: 20 | D33: เท่า
B34: ผลลัพธ์ (คำนวณอัตโนมัติ)
B35: เวลาถึงเลเวล 10 | C35: =INDEX(เลเวล!$R$5:$R$104,10)*60 -> 26.406667 | D35: นาที
B36: เวลาถึงเลเวล 20 | C36: =INDEX(เลเวล!$R$5:$R$104,20) -> 3.2073333 | D36: ชั่วโมง
B37: เวลาถึงเลเวล 30 | C37: =INDEX(เลเวล!$R$5:$R$104,30) -> 10.708111 | D37: ชั่วโมง
B38: เวลาถึงเลเวล 50 | C38: =INDEX(เลเวล!$R$5:$R$104,50) -> 49.658889 | D38: ชั่วโมง
B39: เวลาถึงเลเวลสูงสุด | C39: =INDEX(เลเวล!$R$5:$R$104,C6) -> 400.09311 | D39: ชั่วโมง
B40: ถ้าเล่นวันละ 2 ชั่วโมง | C40: =C39/2 -> 200.04656 | D40: วัน
B41: ฆ่ามอนต่อเลเวล (เลเวล 1) | C41: =INDEX(เลเวล!$P$5:$P$104,1) -> 5 | D41: ตัว
...

Sheet เลเวล
A1: ตารางเลเวล และค่าพลังมอนปกติแต่ละระดับ
A2: สูตรทั้งหมด — แก้ค่าที่ชีต 'ตั้งค่า' แทน · แถวที่เกินเลเวลสูงสุดไม่นับในเวลารวม
A4: เลเวล | B4: EXP ขึ้นเลเวลถัดไป | C4: EXP สะสม | D4: พลังโจมตีผู้เล่น | E4: HP ผู้เล่น | F4: DEF มอน | G4: ดาเมจต่อที | H4: HP มอน | I4: ATK มอน | J4: วินาทีต่อการฆ่า | K4: เป้าหมาย (นาที) | L4: ฆ่าเป้าหมาย | M4: EXP มอน | N4: เบี้ยต่ำสุด | O4: เบี้ยสูงสุด | P4: ต้องฆ่าจริง | Q4: เวลาจริง (นาที) | R4: ชั่วโมงสะสมถึงเลเวลนี้
A5: 1 | B5: =ROUND(ตั้งค่า!$C$24*A5^ตั้งค่า!$C$25,0) -> 15 | C5: =0 -> 0 | D5: =ROUND((ตั้งค่า!$C$12+ตั้งค่า!$C$13*A5)*(1+ตั้งค่า!$C$14)^(A5-1),1) -> 12 | E5: =ROUND((ตั้งค่า!$C$15+ตั้งค่า!$C$16*A5)*(1+ตั้งค่า!$C$17)^(A5-1),0) -> 100 | F5: =ROUND(D5*ตั้งค่า!$C$22,0) -> 1 | G5: =MAX(1,D5-F5) -> 11 | H5: =ROUND(ตั้งค่า!$C$20*G5,0) -> 44 | I5: =MAX(1,ROUND(E5/ตั้งค่า!$C$23,0)) -> 8 | J5: =ตั้งค่า!$C$20*ตั้งค่า!$C$18+ตั้งค่า!$C$21 -> 6.8 | K5: =ตั้งค่า!$C$10*A5^ตั้งค่า!$C$8+ตั้งค่า!$C$9 -> 0.67291183 | L5: =K5*60/J5 -> 5.9374573 | M5: =MAX(1,ROUND(B5/L5,0)) -> 3 | N5: =MAX(1,ROUND(M5*ตั้งค่า!$C$26*(1-ตั้งค่า!$C$27),0)) -> 1 | O5: =MAX(1,ROUND(M5*ตั้งค่า!$C$26*(1+ตั้งค่า!$C$27),0)) -> 2 | P5: =ROUNDUP(B5/M5,0) -> 5 | Q5: =P5*J5/60 -> 0.56666667 | R5: =0 -> 0
A6: 2 | B6: =ROUND(ตั้งค่า!$C$24*A6^ตั้งค่า!$C$25,0) -> 120 | C6: =C5+B5 -> 15 | D6: =ROUND((ตั้งค่า!$C$12+ตั้งค่า!$C$13*A6)*(1+ตั้งค่า!$C$14)^(A6-1),1) -> 14.3 | E6: =ROUND((ตั้งค่า!$C$15+ตั้งค่า!$C$16*A6)*(1+ตั้งค่า!$C$17)^(A6-1),0) -> 112 | F6: =ROUND(D6*ตั้งค่า!$C$22,0) -> 1 | G6: =MAX(1,D6-F6) -> 13.3 | H6: =ROUND(ตั้งค่า!$C$20*G6,0) -> 53 | I6: =MAX(1,ROUND(E6/ตั้งค่า!$C$23,0)) -> 9 | J6: =ตั้งค่า!$C$20*ตั้งค่า!$C$18+ตั้งค่า!$C$21 -> 6.8 | K6: =ตั้งค่า!$C$10*A6^ตั้งค่า!$C$8+ตั้งค่า!$C$9 -> 0.89164733 | L6: =K6*60/J6 -> 7.8674764 | M6: =MAX(1,ROUND(B6/L6,0)) -> 15 | N6: =MAX(1,ROUND(M6*ตั้งค่า!$C$26*(1-ตั้งค่า!$C$27),0)) -> 6 | O6: =MAX(1,ROUND(M6*ตั้งค่า!$C$26*(1+ตั้งค่า!$C$27),0)) -> 9 | P6: =ROUNDUP(B6/M6,0) -> 8 | Q6: =P6*J6/60 -> 0.90666667 | R6: =R5+Q5/60 -> 0.0094444444
A7: 3 | B7: =ROUND(ตั้งค่า!$C$24*A7^ตั้งค่า!$C$25,0) -> 405 | C7: =C6+B6 -> 135 | D7: =ROUND((ตั้งค่า!$C$12+ตั้งค่า!$C$13*A7)*(1+ตั้งค่า!$C$14)^(A7-1),1) -> 16.6 | E7: =ROUND((ตั้งค่า!$C$15+ตั้งค่า!$C$16*A7)*(1+ตั้งค่า!$C$17)^(A7-1),0) -> 124 | F7: =ROUND(D7*ตั้งค่า!$C$22,0) -> 1 | G7: =MAX(1,D7-F7) -> 15.6 | H7: =ROUND(ตั้งค่า!$C$20*G7,0) -> 62 | I7: =MAX(1,ROUND(E7/ตั้งค่า!$C$23,0)) -> 10 | J7: =ตั้งค่า!$C$20*ตั้งค่า!$C$18+ตั้งค่า!$C$21 -> 6.8 | K7: =ตั้งค่า!$C$10*A7^ตั้งค่า!$C$8+ตั้งค่า!$C$9 -> 1.2562065 | L7: =K7*60/J7 -> 11.084175 | M7: =MAX(1,ROUND(B7/L7,0)) -> 37 | N7: =MAX(1,ROUND(M7*ตั้งค่า!$C$26*(1-ตั้งค่า!$C$27),0)) -> 15 | O7: =MAX(1,ROUND(M7*ตั้งค่า!$C$26*(1+ตั้งค่า!$C$27),0)) -> 22 | P7: =ROUNDUP(B7/M7,0) -> 11 | Q7: =P7*J7/60 -> 1.2466667 | R7: =R6+Q6/60 -> 0.024555556
A8: 4 | B8: =ROUND(ตั้งค่า!$C$24*A8^ตั้งค่า!$C$25,0) -> 960 | C8: =C7+B7 -> 540 | D8: =ROUND((ตั้งค่า!$C$12+ตั้งค่า!$C$13*A8)*(1+ตั้งค่า!$C$14)^(A8-1),1) -> 19.1 | E8: =ROUND((ตั้งค่า!$C$15+ตั้งค่า!$C$16*A8)*(1+ตั้งค่า!$C$17)^(A8-1),0) -> 136 | F8: =ROUND(D8*ตั้งค่า!$C$22,0) -> 1 | G8: =MAX(1,D8-F8) -> 18.1 | H8: =ROUND(ตั้งค่า!$C$20*G8,0) -> 72 | I8: =MAX(1,ROUND(E8/ตั้งค่า!$C$23,0)) -> 11 | J8: =ตั้งค่า!$C$20*ตั้งค่า!$C$18+ตั้งค่า!$C$21 -> 6.8 | K8: =ตั้งค่า!$C$10*A8^ตั้งค่า!$C$8+ตั้งค่า!$C$9 -> 1.7665893 | L8: =K8*60/J8 -> 15.587553 | M8: =MAX(1,ROUND(B8/L8,0)) -> 62 | N8: =MAX(1,ROUND(M8*ตั้งค่า!$C$26*(1-ตั้งค่า!$C$27),0)) -> 25 | O8: =MAX(1,ROUND(M8*ตั้งค่า!$C$26*(1+ตั้งค่า!$C$27),0)) -> 37 | P8: =ROUNDUP(B8/M8,0) -> 16 | Q8: =P8*J8/60 -> 1.8133333 | R8: =R7+Q7/60 -> 0.045333333
A9: 5 | B9: =ROUND(ตั้งค่า!$C$24*A9^ตั้งค่า!$C$25,0) -> 1875 | C9: =C8+B8 -> 1500 | D9: =ROUND((ตั้งค่า!$C$12+ตั้งค่า!$C$13*A9)*(1+ตั้งค่า!$C$14)^(A9-1),1) -> 21.6 | E9: =ROUND((ตั้งค่า!$C$15+ตั้งค่า!$C$16*A9)*(1+ตั้งค่า!$C$17)^(A9-1),0) -> 149 | F9: =ROUND(D9*ตั้งค่า!$C$22,0) -> 1 | G9: =MAX(1,D9-F9) -> 20.6 | H9: =ROUND(ตั้งค่า!$C$20*G9,0) -> 82 | I9: =MAX(1,ROUND(E9/ตั้งค่า!$C$23,0)) -> 12 | J9: =ตั้งค่า!$C$20*ตั้งค่า!$C$18+ตั้งค่า!$C$21 -> 6.8 | K9: =ตั้งค่า!$C$10*A9^ตั้งค่า!$C$8+ตั้งค่า!$C$9 -> 2.4227958 | L9: =K9*60/J9 -> 21.37761 | M9: =MAX(1,ROUND(B9/L9,0)) -> 88 | N9: =MAX(1,ROUND(M9*ตั้งค่า!$C$26*(1-ตั้งค่า!$C$27),0)) -> 35 | O9: =MAX(1,ROUND(M9*ตั้งค่า!$C$26*(1+ตั้งค่า!$C$27),0)) -> 53 | P9: =ROUNDUP(B9/M9,0) -> 22 | Q9: =P9*J9/60 -> 2.4933333 | R9: =R8+Q8/60 -> 0.075555556
A10: 6 | B10: =ROUND(ตั้งค่า!$C$24*A10^ตั้งค่า!$C$25,0) -> 3240 | C10: =C9+B9 -> 3375 | D10: =ROUND((ตั้งค่า!$C$12+ตั้งค่า!$C$13*A10)*(1+ตั้งค่า!$C$14)^(A10-1),1) -> 24.3 | E10: =ROUND((ตั้งค่า!$C$15+ตั้งค่า!$C$16*A10)*(1+ตั้งค่า!$C$17)^(A10-1),0) -> 162 | F10: =ROUND(D10*ตั้งค่า!$C$22,0) -> 1 | G10: =MAX(1,D10-F10) -> 23.3 | H10: =ROUND(ตั้งค่า!$C$20*G10,0) -> 93 | I10: =MAX(1,ROUND(E10/ตั้งค่า!$C$23,0)) -> 14 | J10: =ตั้งค่า!$C$20*ตั้งค่า!$C$18+ตั้งค่า!$C$21 -> 6.8 | K10: =ตั้งค่า!$C$10*A10^ตั้งค่า!$C$8+ตั้งค่า!$C$9 -> 3.2248259 | L10: =K10*60/J10 -> 28.454347 | M10: =MAX(1,ROUND(B10/L10,0)) -> 114 | N10: =MAX(1,ROUND(M10*ตั้งค่า!$C$26*(1-ตั้งค่า!$C$27),0)) -> 46 | O10: =MAX(1,ROUND(M10*ตั้งค่า!$C$26*(1+ตั้งค่า!$C$27),0)) -> 68 | P10: =ROUNDUP(B10/M10,0) -> 29 | Q10: =P10*J10/60 -> 3.2866667 | R10: =R9+Q9/60 -> 0.11711111
A11: 7 | B11: =ROUND(ตั้งค่า!$C$24*A11^ตั้งค่า!$C$25,0) -> 5145 | C11: =C10+B10 -> 6615 | D11: =ROUND((ตั้งค่า!$C$12+ตั้งค่า!$C$13*A11)*(1+ตั้งค่า!$C$14)^(A11-1),1) -> 27 | E11: =ROUND((ตั้งค่า!$C$15+ตั้งค่า!$C$16*A11)*(1+ตั้งค่า!$C$17)^(A11-1),0) -> 175 | F11: =ROUND(D11*ตั้งค่า!$C$22,0) -> 1 | G11: =MAX(1,D11-F11) -> 26 | H11: =ROUND(ตั้งค่า!$C$20*G11,0) -> 104 | I11: =MAX(1,ROUND(E11/ตั้งค่า!$C$23,0)) -> 15 | J11: =ตั้งค่า!$C$20*ตั้งค่า!$C$18+ตั้งค่า!$C$21 -> 6.8 | K11: =ตั้งค่า!$C$10*A11^ตั้งค่า!$C$8+ตั้งค่า!$C$9 -> 4.1726798 | L11: =K11*60/J11 -> 36.817763 | M11: =MAX(1,ROUND(B11/L11,0)) -> 140 | N11: =MAX(1,ROUND(M11*ตั้งค่า!$C$26*(1-ตั้งค่า!$C$27),0)) -> 56 | O11: =MAX(1,ROUND(M11*ตั้งค่า!$C$26*(1+ตั้งค่า!$C$27),0)) -> 84 | P11: =ROUNDUP(B11/M11,0) -> 37 | Q11: =P11*J11/60 -> 4.1933333 | R11: =R10+Q10/60 -> 0.17188889
A12: 8 | B12: =ROUND(ตั้งค่า!$C$24*A12^ตั้งค่า!$C$25,0) -> 7680 | C12: =C11+B11 -> 11760 | D12: =ROUND((ตั้งค่า!$C$12+ตั้งค่า!$C$13*A12)*(1+ตั้งค่า!$C$14)^(A12-1),1) -> 29.9 | E12: =ROUND((ตั้งค่า!$C$15+ตั้งค่า!$C$16*A12)*(1+ตั้งค่า!$C$17)^(A12-1),0) -> 189 | F12: =ROUND(D12*ตั้งค่า!$C$22,0) -> 1 | G12: =MAX(1,D12-F12) -> 28.9 | H12: =ROUND(ตั้งค่า!$C$20*G12,0) -> 116 | I12: =MAX(1,ROUND(E12/ตั้งค่า!$C$23,0)) -> 16 | J12: =ตั้งค่า!$C$20*ตั้งค่า!$C$18+ตั้งค่า!$C$21 -> 6.8 | K12: =ตั้งค่า!$C$10*A12^ตั้งค่า!$C$8+ตั้งค่า!$C$9 -> 5.2663572 | L12: =K12*60/J12 -> 46.467858 | M12: =MAX(1,ROUND(B12/L12,0)) -> 165 | N12: =MAX(1,ROUND(M12*ตั้งค่า!$C$26*(1-ตั้งค่า!$C$27),0)) -> 66 | O12: =MAX(1,ROUND(M12*ตั้งค่า!$C$26*(1+ตั้งค่า!$C$27),0)) -> 99 | P12: =ROUNDUP(B12/M12,0) -> 47 | Q12: =P12*J12/60 -> 5.3266667 | R12: =R11+Q11/60 -> 0.24177778
A13: 9 | B13: =ROUND(ตั้งค่า!$C$24*A13^ตั้งค่า!$C$25,0) -> 10935 | C13: =C12+B12 -> 19440 | D13: =ROUND((ตั้งค่า!$C$12+ตั้งค่า!$C$13*A13)*(1+ตั้งค่า!$C$14)^(A13-1),1) -> 32.8 | E13: =ROUND((ตั้งค่า!$C$15+ตั้งค่า!$C$16*A13)*(1+ตั้งค่า!$C$17)^(A13-1),0) -> 203 | F13: =ROUND(D13*ตั้งค่า!$C$22,0) -> 2 | G13: =MAX(1,D13-F13) -> 30.8 | H13: =ROUND(ตั้งค่า!$C$20*G13,0) -> 123 | I13: =MAX(1,ROUND(E13/ตั้งค่า!$C$23,0)) -> 17 | J13: =ตั้งค่า!$C$20*ตั้งค่า!$C$18+ตั้งค่า!$C$21 -> 6.8 | K13: =ตั้งค่า!$C$10*A13^ตั้งค่า!$C$8+ตั้งค่า!$C$9 -> 6.5058584 | L13: =K13*60/J13 -> 57.404633 | M13: =MAX(1,ROUND(B13/L13,0)) -> 190 | N13: =MAX(1,ROUND(M13*ตั้งค่า!$C$26*(1-ตั้งค่า!$C$27),0)) -> 76 | O13: =MAX(1,ROUND(M13*ตั้งค่า!$C$26*(1+ตั้งค่า!$C$27),0)) -> 114 | P13: =ROUNDUP(B13/M13,0) -> 58 | Q13: =P13*J13/60 -> 6.5733333 | R13: =R12+Q12/60 -> 0.33055556
A14: 10 | B14: =ROUND(ตั้งค่า!$C$24*A14^ตั้งค่า!$C$25,0) -> 15000 | C14: =C13+B13 -> 30375 | D14: =ROUND((ตั้งค่า!$C$12+ตั้งค่า!$C$13*A14)*(1+ตั้งค่า!$C$14)^(A14-1),1) -> 35.9 | E14: =ROUND((ตั้งค่า!$C$15+ตั้งค่า!$C$16*A14)*(1+ตั้งค่า!$C$17)^(A14-1),0) -> 217 | F14: =ROUND(D14*ตั้งค่า!$C$22,0) -> 2 | G14: =MAX(1,D14-F14) -> 33.9 | H14: =ROUND(ตั้งค่า!$C$20*G14,0) -> 136 | I14: =MAX(1,ROUND(E14/ตั้งค่า!$C$23,0)) -> 18 | J14: =ตั้งค่า!$C$20*ตั้งค่า!$C$18+ตั้งค่า!$C$21 -> 6.8 | K14: =ตั้งค่า!$C$10*A14^ตั้งค่า!$C$8+ตั้งค่า!$C$9 -> 7.8911832 | L14: =K14*60/J14 -> 69.628087 | M14: =MAX(1,ROUND(B14/L14,0)) -> 215 | N14: =MAX(1,ROUND(M14*ตั้งค่า!$C$26*(1-ตั้งค่า!$C$27),0)) -> 86 | O14: =MAX(1,ROUND(M14*ตั้งค่า!$C$26*(1+ตั้งค่า!$C$27),0)) -> 129 | P14: =ROUNDUP(B14/M14,0) -> 70 | Q14: =P14*J14/60 -> 7.9333333 | R14: =R13+Q13/60 -> 0.44011111
A15: 11 | B15: =ROUND(ตั้งค่า!$C$24*A15^ตั้งค่า!$C$25,0) -> 19965 | C15: =C14+B14 -> 45375 | D15: =ROUND((ตั้งค่า!$C$12+ตั้งค่า!$C$13*A15)*(1+ตั้งค่า!$C$14)^(A15-1),1) -> 39 | E15: =ROUND((ตั้งค่า!$C$15+ตั้งค่า!$C$16*A15)*(1+ตั้งค่า!$C$17)^(A15-1),0) -> 232 | F15: =ROUND(D15*ตั้งค่า!$C$22,0) -> 2 | G15: =MAX(1,D15-F15) -> 37 | H15: =ROUND(ตั้งค่า!$C$20*G15,0) -> 148 | I15: =MAX(1,ROUND(E15/ตั้งค่า!$C$23,0)) -> 19 | J15: =ตั้งค่า!$C$20*ตั้งค่า!$C$18+ตั้งค่า!$C$21 -> 6.8 | K15: =ตั้งค่า!$C$10*A15^ตั้งค่า!$C$8+ตั้งค่า!$C$9 -> 9.4223317 | L15: =K15*60/J15 -> 83.138221 | M15: =MAX(1,ROUND(B15/L15,0)) -> 240 | N15: =MAX(1,ROUND(M15*ตั้งค่า!$C$26*(1-ตั้งค่า!$C$27),0)) -> 96 | O15: =MAX(1,ROUND(M15*ตั้งค่า!$C$26*(1+ตั้งค่า!$C$27),0)) -> 144 | P15: =ROUNDUP(B15/M15,0) -> 84 | Q15: =P15*J15/60 -> 9.52 | R15: =R14+Q14/60 -> 0.57233333
A16: 12 | B16: =ROUND(ตั้งค่า!$C$24*A16^ตั้งค่า!$C$25,0) -> 25920 | C16: =C15+B15 -> 65340 | D16: =ROUND((ตั้งค่า!$C$12+ตั้งค่า!$C$13*A16)*(1+ตั้งค่า!$C$14)^(A16-1),1) -> 42.3 | E16: =ROUND((ตั้งค่า!$C$15+ตั้งค่า!$C$16*A16)*(1+ตั้งค่า!$C$17)^(A16-1),0) -> 247 | F16: =ROUND(D16*ตั้งค่า!$C$22,0) -> 2 | G16: =MAX(1,D16-F16) -> 40.3 | H16: =ROUND(ตั้งค่า!$C$20*G16,0) -> 161 | I16: =MAX(1,ROUND(E16/ตั้งค่า!$C$23,0)) -> 21 | J16: =ตั้งค่า!$C$20*ตั้งค่า!$C$18+ตั้งค่า!$C$21 -> 6.8 | K16: =ตั้งค่า!$C$10*A16^ตั้งค่า!$C$8+ตั้งค่า!$C$9 -> 11.099304 | L16: =K16*60/J16 -> 97.935033 | M16: =MAX(1,ROUND(B16/L16,0)) -> 265 | N16: =MAX(1,ROUND(M16*ตั้งค่า!$C$26*(1-ตั้งค่า!$C$27),0)) -> 106 | O16: =MAX(1,ROUND(M16*ตั้งค่า!$C$26*(1+ตั้งค่า!$C$27),0)) -> 159 | P16: =ROUNDUP(B16/M16,0) -> 98 | Q16: =P16*J16/60 -> 11.106667 | R16: =R15+Q15/60 -> 0.731
A17: 13 | B17: =ROUND(ตั้งค่า!$C$24*A17^ตั้งค่า!$C$25,0) -> 32955 | C17: =C16+B16 -> 91260 | D17: =ROUND((ตั้งค่า!$C$12+ตั้งค่า!$C$13*A17)*(1+ตั้งค่า!$C$14)^(A17-1),1) -> 45.7 | E17: =ROUND((ตั้งค่า!$C$15+ตั้งค่า!$C$16*A17)*(1+ตั้งค่า!$C$17)^(A17-1),0) -> 263 | F17: =ROUND(D17*ตั้งค่า!$C$22,0) -> 2 | G17: =MAX(1,D17-F17) -> 43.7 | H17: =ROUND(ตั้งค่า!$C$20*G17,0) -> 175 | I17: =MAX(1,ROUND(E17/ตั้งค่า!$C$23,0)) -> 22 | J17: =ตั้งค่า!$C$20*ตั้งค่า!$C$18+ตั้งค่า!$C$21 -> 6.8 | K17: =ตั้งค่า!$C$10*A17^ตั้งค่า!$C$8+ตั้งค่า!$C$9 -> 12.9221 | L17: =K17*60/J17 -> 114.01853 | M17: =MAX(1,ROUND(B17/L17,0)) -> 289 | N17: =MAX(1,ROUND(M17*ตั้งค่า!$C$26*(1-ตั้งค่า!$C$27),0)) -> 116 | O17: =MAX(1,ROUND(M17*ตั้งค่า!$C$26*(1+ตั้งค่า!$C$27),0)) -> 173 | P17: =ROUNDUP(B17/M17,0) -> 115 | Q17: =P17*J17/60 -> 13.033333 | R17: =R16+Q16/60 -> 0.91611111
... A104: 100 | B104: =ROUND(ตั้งค่า!$C$24*A104^ตั้งค่า!$C$25,0) -> 15000000 | C104: =C103+B103 -> 367537500 | D104: =ROUND((ตั้งค่า!$C$12+ตั้งค่า!$C$13*A104)*(1+ตั้งค่า!$C$14)^(A104-1),1) -> 1491.5 | E104: =ROUND((ตั้งค่า!$C$15+ตั้งค่า!$C$16*A104)*(1+ตั้งค่า!$C$17)^(A104-1),0) -> 4760 | F104: =ROUND(D104*ตั้งค่า!$C$22,0) -> 75 | G104: =MAX(1,D104-F104) -> 1416.5 | H104: =ROUND(ตั้งค่า!$C$20*G104,0) -> 5666 | I104: =MAX(1,ROUND(E104/ตั้งค่า!$C$23,0)) -> 397 | J104: =ตั้งค่า!$C$20*ตั้งค่า!$C$18+ตั้งค่า!$C$21 -> 6.8 | K104: =ตั้งค่า!$C$10*A104^ตั้งค่า!$C$8+ตั้งค่า!$C$9 -> 729.71832 | L104: =K104*60/J104 -> 6438.691 | M104: =MAX(1,ROUND(B104/L104,0)) -> 2330 | N104: =MAX(1,ROUND(M104*ตั้งค่า!$C$26*(1-ตั้งค่า!$C$27),0)) -> 932 | O104: =MAX(1,ROUND(M104*ตั้งค่า!$C$26*(1+ตั้งค่า!$C$27),0)) -> 1398 | P104: =ROUNDUP(B104/M104,0) -> 6438 | Q104: =P104*J104/60 -> 729.64 | R104: =R103+Q103/60 -> 400.09311

Sheet มอน
A1: มอนสเตอร์ (ร่างแรก — ชื่อ แมพ เลเวล แก้ได้)
A2: สีน้ำเงิน = แก้ได้ · ตัวคูณ HP/EXP ใช้ทำมอนถึกหรือมอนเปราะในเลเวลเดียวกัน · ประเภทพิมพ์ 'ปกติ' หรือ 'บอส'
A4: ชื่อ | B4: แมพ | C4: เลเวล | D4: ประเภท | E4: นิสัย | F4: ตัวคูณ HP | G4: ตัวคูณ EXP | H4: HP | I4: DEF | J4: ATK | K4: EXP | L4: เบี้ยต่ำสุด | M4: เบี้ยสูงสุด | N4: ตีกี่ทีตาย | O4: ลักษณะ
A5: ข้าวเหนียวปั้น | B5: ทุ่งนาริมคลอง | C5: 1 | D5: ปกติ | E5: ไม่ตีก่อน | F5: 1 | G5: 1 | H5: =ROUND(INDEX(เลเวล!$H$5:$H$104,C5)*F5*IF(D5="บอส",ตั้งค่า!$C$29,1),0) -> 44 | I5: =ROUND(INDEX(เลเวล!$F$5:$F$104,C5)*IF(D5="บอส",ตั้งค่า!$C$32,1),0) -> 1 | J5: =ROUND(INDEX(เลเวล!$I$5:$I$104,C5)*IF(D5="บอส",ตั้งค่า!$C$31,1),0) -> 8 | K5: =ROUND(INDEX(เลเวล!$M$5:$M$104,C5)*G5*IF(D5="บอส",ตั้งค่า!$C$30,1),0) -> 3 | L5: =ROUND(INDEX(เลเวล!$N$5:$N$104,C5)*IF(D5="บอส",ตั้งค่า!$C$33,1),0) -> 1 | M5: =ROUND(INDEX(เลเวล!$O$5:$O$104,C5)*IF(D5="บอส",ตั้งค่า!$C$33,1),0) -> 2 | N5: =ROUNDUP(H5/INDEX(เลเวล!$G$5:$G$104,C5),0) -> 4 | O5: ก้อนข้าวเหนียวมีตา กระโดดดึ๋ง ๆ มอนตัวแรกของเกม
A6: หิ่งห้อยนา | B6: ทุ่งนาริมคลอง | C6: 2 | D6: ปกติ | E6: ไม่ตีก่อน | F6: 0.7 | G6: 0.8 | H6: =ROUND(INDEX(เลเวล!$H$5:$H$104,C6)*F6*IF(D6="บอส",ตั้งค่า!$C$29,1),0) -> 37 | I6: =ROUND(INDEX(เลเวล!$F$5:$F$104,C6)*IF(D6="บอส",ตั้งค่า!$C$32,1),0) -> 1 | J6: =ROUND(INDEX(เลเวล!$I$5:$I$104,C6)*IF(D6="บอส",ตั้งค่า!$C$31,1),0) -> 9 | K6: =ROUND(INDEX(เลเวล!$M$5:$M$104,C6)*G6*IF(D6="บอส",ตั้งค่า!$C$30,1),0) -> 12 | L6: =ROUND(INDEX(เลเวล!$N$5:$N$104,C6)*IF(D6="บอส",ตั้งค่า!$C$33,1),0) -> 6 | M6: =ROUND(INDEX(เลเวล!$O$5:$O$104,C6)*IF(D6="บอส",ตั้งค่า!$C$33,1),0) -> 9 | N6: =ROUNDUP(H6/INDEX(เลเวล!$G$5:$G$104,C6),0) -> 3 | O6: บินหลบไปมา ตัวเปราะ
A7: ปูนา | B7: ทุ่งนาริมคลอง | C7: 1 | D7: ปกติ | E7: ไม่ตีก่อน | F7: 1.3 | G7: 1.15 | H7: =ROUND(INDEX(เลเวล!$H$5:$H$104,C7)*F7*IF(D7="บอส",ตั้งค่า!$C$29,1),0) -> 57 | I7: =ROUND(INDEX(เลเวล!$F$5:$F$104,C7)*IF(D7="บอส",ตั้งค่า!$C$32,1),0) -> 1 | J7: =ROUND(INDEX(เลเวล!$I$5:$I$104,C7)*IF(D7="บอส",ตั้งค่า!$C$31,1),0) -> 8 | K7: =ROUND(INDEX(เลเวล!$M$5:$M$104,C7)*G7*IF(D7="บอส",ตั้งค่า!$C$30,1),0) -> 3 | L7: =ROUND(INDEX(เลเวล!$N$5:$N$104,C7)*IF(D7="บอส",ตั้งค่า!$C$33,1),0) -> 1 | M7: =ROUND(INDEX(เลเวล!$O$5:$O$104,C7)*IF(D7="บอส",ตั้งค่า!$C$33,1),0) -> 2 | N7: =ROUNDUP(H7/INDEX(เลเวล!$G$5:$G$104,C7),0) -> 6 | O7: กระดองแข็ง ถึกกว่าปกติ
A8: หอยเชอรี่ | B8: ทุ่งนาริมคลอง | C8: 4 | D8: ปกติ | E8: ไม่ตีก่อน | F8: 1.4 | G8: 1.2 | H8: =ROUND(INDEX(เลเวล!$H$5:$H$104,C8)*F8*IF(D8="บอส",ตั้งค่า!$C$29,1),0) -> 101 | I8: =ROUND(INDEX(เลเวล!$F$5:$F$104,C8)*IF(D8="บอส",ตั้งค่า!$C$32,1),0) -> 1 | J8: =ROUND(INDEX(เลเวล!$I$5:$I$104,C8)*IF(D8="บอส",ตั้งค่า!$C$31,1),0) -> 11 | K8: =ROUND(INDEX(เลเวล!$M$5:$M$104,C8)*G8*IF(D8="บอส",ตั้งค่า!$C$30,1),0) -> 74 | L8: =ROUND(INDEX(เลเวล!$N$5:$N$104,C8)*IF(D8="บอส",ตั้งค่า!$C$33,1),0) -> 25 | M8: =ROUND(INDEX(เลเวล!$O$5:$O$104,C8)*IF(D8="บอส",ตั้งค่า!$C$33,1),0) -> 37 | N8: =ROUNDUP(H8/INDEX(เลเวล!$G$5:$G$104,C8),0) -> 6 | O8: ช้าแต่ถึก
A9: กบเขียว | B9: ทุ่งนาริมคลอง | C9: 5 | D9: ปกติ | E9: ไม่ตีก่อน | F9: 1 | G9: 1 | H9: =ROUND(INDEX(เลเวล!$H$5:$H$104,C9)*F9*IF(D9="บอส",ตั้งค่า!$C$29,1),0) -> 82 | I9: =ROUND(INDEX(เลเวล!$F$5:$F$104,C9)*IF(D9="บอส",ตั้งค่า!$C$32,1),0) -> 1 | J9: =ROUND(INDEX(เลเวล!$I$5:$I$104,C9)*IF(D9="บอส",ตั้งค่า!$C$31,1),0) -> 12 | K9: =ROUND(INDEX(เลเวล!$M$5:$M$104,C9)*G9*IF(D9="บอส",ตั้งค่า!$C$30,1),0) -> 88 | L9: =ROUND(INDEX(เลเวล!$N$5:$N$104,C9)*IF(D9="บอส",ตั้งค่า!$C$33,1),0) -> 35 | M9: =ROUND(INDEX(เลเวล!$O$5:$O$104,C9)*IF(D9="บอส",ตั้งค่า!$C$33,1),0) -> 53 | N9: =ROUNDUP(H9/INDEX(เลเวล!$G$5:$G$104,C9),0) -> 4 | O9: กระโดดไกล
A10: ควายน้อยขี้หงุดหงิด | B10: ทุ่งนาริมคลอง | C10: 7 | D10: ปกติ | E10: ตีก่อน | F10: 1.2 | G10: 1.15 | H10: =ROUND(INDEX(เลเวล!$H$5:$H$104,C10)*F10*IF(D10="บอส",ตั้งค่า!$C$29,1),0) -> 125 | I10: =ROUND(INDEX(เลเวล!$F$5:$F$104,C10)*IF(D10="บอส",ตั้งค่า!$C$32,1),0) -> 1 | J10: =ROUND(INDEX(เลเวล!$I$5:$I$104,C10)*IF(D10="บอส",ตั้งค่า!$C$31,1),0) -> 15 | K10: =ROUND(INDEX(เลเวล!$M$5:$M$104,C10)*G10*IF(D10="บอส",ตั้งค่า!$C$30,1),0) -> 161 | L10: =ROUND(INDEX(เลเวล!$N$5:$N$104,C10)*IF(D10="บอส",ตั้งค่า!$C$33,1),0) -> 56 | M10: =ROUND(INDEX(เลเวล!$O$5:$O$104,C10)*IF(D10="บอส",ตั้งค่า!$C$33,1),0) -> 84 | N10: =ROUNDUP(H10/INDEX(เลเวล!$G$5:$G$104,C10),0) -> 5 | O10: พุ่งชนเมื่อเข้าใกล้
A11: หุ่นไล่กาเดินได้ | B11: ทุ่งนาริมคลอง | C11: 8 | D11: ปกติ | E11: ตีก่อน | F11: 1 | G11: 1 | H11: =ROUND(INDEX(เลเวล!$H$5:$H$104,C11)*F11*IF(D11="บอส",ตั้งค่า!$C$29,1),0) -> 116 | I11: =ROUND(INDEX(เลเวล!$F$5:$F$104,C11)*IF(D11="บอส",ตั้งค่า!$C$32,1),0) -> 1 | J11: =ROUND(INDEX(เลเวล!$I$5:$I$104,C11)*IF(D11="บอส",ตั้งค่า!$C$31,1),0) -> 16 | K11: =ROUND(INDEX(เลเวล!$M$5:$M$104,C11)*G11*IF(D11="บอส",ตั้งค่า!$C$30,1),0) -> 165 | L11: =ROUND(INDEX(เลเวล!$N$5:$N$104,C11)*IF(D11="บอส",ตั้งค่า!$C$33,1),0) -> 66 | M11: =ROUND(INDEX(เลเวล!$O$5:$O$104,C11)*IF(D11="บอส",ตั้งค่า!$C$33,1),0) -> 99 | N11: =ROUNDUP(H11/INDEX(เลเวล!$G$5:$G$104,C11),0) -> 5 | O11: ฟาดด้วยไม้ไผ่
A12: หุ่นไล่กายักษ์ | B12: ทุ่งนาริมคลอง | C12: 10 | D12: บอส | E12: ตีก่อน | F12: 1 | G12: 1 | H12: =ROUND(INDEX(เลเวล!$H$5:$H$104,C12)*F12*IF(D12="บอส",ตั้งค่า!$C$29,1),0) -> 5440 | I12: =ROUND(INDEX(เลเวล!$F$5:$F$104,C12)*IF(D12="บอส",ตั้งค่า!$C$32,1),0) -> 4 | J12: =ROUND(INDEX(เลเวล!$I$5:$I$104,C12)*IF(D12="บอส",ตั้งค่า!$C$31,1),0) -> 45 | K12: =ROUND(INDEX(เลเวล!$M$5:$M$104,C12)*G12*IF(D12="บอส",ตั้งค่า!$C$30,1),0) -> 5375 | L12: =ROUND(INDEX(เลเวล!$N$5:$N$104,C12)*IF(D12="บอส",ตั้งค่า!$C$33,1),0) -> 1720 | M12: =ROUND(INDEX(เลเวล!$O$5:$O$104,C12)*IF(D12="บอส",ตั้งค่า!$C$33,1),0) -> 2580 | N12: =ROUNDUP(H12/INDEX(เลเวล!$G$5:$G$104,C12),0) -> 161 | O12: บอสแรก เกิดทุก 30 นาที
A13: ลิงแสมซน | B13: ป่าไผ่ริมบึง | C13: 11 | D13: ปกติ | E13: ไม่ตีก่อน | F13: 0.8 | G13: 0.9 | H13: =ROUND(INDEX(เลเวล!$H$5:$H$104,C13)*F13*IF(D13="บอส",ตั้งค่า!$C$29,1),0) -> 118 | I13: =ROUND(INDEX(เลเวล!$F$5:$F$104,C13)*IF(D13="บอส",ตั้งค่า!$C$32,1),0) -> 2 | J13: =ROUND(INDEX(เลเวล!$I$5:$I$104,C13)*IF(D13="บอส",ตั้งค่า!$C$31,1),0) -> 19 | K13: =ROUND(INDEX(เลเวล!$M$5:$M$104,C13)*G13*IF(D13="บอส",ตั้งค่า!$C$30,1),0) -> 216 | L13: =ROUND(INDEX(เลเวล!$N$5:$N$104,C13)*IF(D13="บอส",ตั้งค่า!$C$33,1),0) -> 96 | M13: =ROUND(INDEX(เลเวล!$O$5:$O$104,C13)*IF(D13="บอส",ตั้งค่า!$C$33,1),0) -> 144 | N13: =ROUNDUP(H13/INDEX(เลเวล!$G$5:$G$104,C13),0) -> 4 | O13: ขโมยของแล้ววิ่งหนี
A14: ตะขาบไฟ | B14: ป่าไผ่ริมบึง | C14: 13 | D14: ปกติ | E14: ตีก่อน | F14: 1 | G14: 1.05 | H14: =ROUND(INDEX(เลเวล!$H$5:$H$104,C14)*F14*IF(D14="บอส",ตั้งค่า!$C$29,1),0) -> 175 | I14: =ROUND(INDEX(เลเวล!$F$5:$F$104,C14)*IF(D14="บอส",ตั้งค่า!$C$32,1),0) -> 2 | J14: =ROUND(INDEX(เลเวล!$I$5:$I$104,C14)*IF(D14="บอส",ตั้งค่า!$C$31,1),0) -> 22 | K14: =ROUND(INDEX(เลเวล!$M$5:$M$104,C14)*G14*IF(D14="บอส",ตั้งค่า!$C$30,1),0) -> 303 | L14: =ROUND(INDEX(เลเวล!$N$5:$N$104,C14)*IF(D14="บอส",ตั้งค่า!$C$33,1),0) -> 116 | M14: =ROUND(INDEX(เลเวล!$O$5:$O$104,C14)*IF(D14="บอส",ตั้งค่า!$C$33,1),0) -> 173 | N14: =ROUNDUP(H14/INDEX(เลเวล!$G$5:$G$104,C14),0) -> 5 | O14: พิษไฟ
A15: เห็ดโคนเดินได้ | B15: ป่าไผ่ริมบึง | C15: 14 | D15: ปกติ | E15: ไม่ตีก่อน | F15: 1.1 | G15: 1.05 | H15: =ROUND(INDEX(เลเวล!$H$5:$H$104,C15)*F15*IF(D15="บอส",ตั้งค่า!$C$29,1),0) -> 208 | I15: =ROUND(INDEX(เลเวล!$F$5:$F$104,C15)*IF(D15="บอส",ตั้งค่า!$C$32,1),0) -> 2 | J15: =ROUND(INDEX(เลเวล!$I$5:$I$104,C15)*IF(D15="บอส",ตั้งค่า!$C$31,1),0) -> 23 | K15: =ROUND(INDEX(เลเวล!$M$5:$M$104,C15)*G15*IF(D15="บอส",ตั้งค่า!$C$30,1),0) -> 329 | L15: =ROUND(INDEX(เลเวล!$N$5:$N$104,C15)*IF(D15="บอส",ตั้งค่า!$C$33,1),0) -> 125 | M15: =ROUND(INDEX(เลเวล!$O$5:$O$104,C15)*IF(D15="บอส",ตั้งค่า!$C$33,1),0) -> 188 | N15: =ROUNDUP(H15/INDEX(เลเวล!$G$5:$G$104,C15),0) -> 5 | O15: ปล่อยสปอร์
A16: ผีพรายน้ำ | B16: ป่าไผ่ริมบึง | C16: 16 | D16: ปกติ | E16: ตีก่อน | F16: 0.9 | G16: 1.1 | H16: =ROUND(INDEX(เลเวล!$H$5:$H$104,C16)*F16*IF(D16="บอส",ตั้งค่า!$C$29,1),0) -> 193 | I16: =ROUND(INDEX(เลเวล!$F$5:$F$104,C16)*IF(D16="บอส",ตั้งค่า!$C$32,1),0) -> 3 | J16: =ROUND(INDEX(เลเวล!$I$5:$I$104,C16)*IF(D16="บอส",ตั้งค่า!$C$31,1),0) -> 26 | K16: =ROUND(INDEX(เลเวล!$M$5:$M$104,C16)*G16*IF(D16="บอส",ตั้งค่า!$C$30,1),0) -> 397 | L16: =ROUND(INDEX(เลเวล!$N$5:$N$104,C16)*IF(D16="บอส",ตั้งค่า!$C$33,1),0) -> 144 | M16: =ROUND(INDEX(เลเวล!$O$5:$O$104,C16)*IF(D16="บอส",ตั้งค่า!$C$33,1),0) -> 217 | N16: =ROUNDUP(H16/INDEX(เลเวล!$G$5:$G$104,C16),0) -> 4 | O16: โผล่จากน้ำ
... A40: พญาเหยี่ยวเพลิง | B40: หิมพานต์ชั้นใน | C40: 92 | D40: ปกติ | E40: ตีก่อน | F40: 1 | G40: 1.05 | H40: =ROUND(INDEX(เลเวล!$H$5:$H$104,C40)*F40*IF(D40="บอส",ตั้งค่า!$C$29,1),0) -> 4468 | I40: =ROUND(INDEX(เลเวล!$F$5:$F$104,C40)*IF(D40="บอส",ตั้งค่า!$C$32,1),0) -> 59 | J40: =ROUND(INDEX(เลเวล!$I$5:$I$104,C40)*IF(D40="บอส",ตั้งค่า!$C$31,1),0) -> 326 | K40: =ROUND(INDEX(เลเวล!$M$5:$M$104,C40)*G40*IF(D40="บอส",ตั้งค่า!$C$30,1),0) -> 2250 | L40: =ROUND(INDEX(เลเวล!$N$5:$N$104,C40)*IF(D40="บอส",ตั้งค่า!$C$33,1),0) -> 857 | M40: =ROUND(INDEX(เลเวล!$O$5:$O$104,C40)*IF(D40="บอส",ตั้งค่า!$C$33,1),0) -> 1286 | N40: =ROUNDUP(H40/INDEX(เลเวล!$G$5:$G$104,C40),0) -> 4 | O40: พ่นไฟ
A41: วิญญาณอสูรโบราณ | B41: หิมพานต์ชั้นใน | C41: 96 | D41: ปกติ | E41: ตีก่อน | F41: 1.3 | G41: 1.2 | H41: =ROUND(INDEX(เลเวล!$H$5:$H$104,C41)*F41*IF(D41="บอส",ตั้งค่า!$C$29,1),0) -> 6549 | I41: =ROUND(INDEX(เลเวล!$F$5:$F$104,C41)*IF(D41="บอส",ตั้งค่า!$C$32,1),0) -> 66 | J41: =ROUND(INDEX(เลเวล!$I$5:$I$104,C41)*IF(D41="บอส",ตั้งค่า!$C$31,1),0) -> 360 | K41: =ROUND(INDEX(เลเวล!$M$5:$M$104,C41)*G41*IF(D41="บอส",ตั้งค่า!$C$30,1),0) -> 2683 | L41: =ROUND(INDEX(เลเวล!$N$5:$N$104,C41)*IF(D41="บอส",ตั้งค่า!$C$33,1),0) -> 894 | M41: =ROUND(INDEX(เลเวล!$O$5:$O$104,C41)*IF(D41="บอส",ตั้งค่า!$C$33,1),0) -> 1342 | N41: =ROUNDUP(H41/INDEX(เลเวล!$G$5:$G$104,C41),0) -> 6
A42: จอมอสูรหิมพานต์ | B42: หิมพานต์ชั้นใน | C42: 100 | D42: บอส | E42: ตีก่อน | F42: 1 | G42: 1 | H42: =ROUND(INDEX(เลเวล!$H$5:$H$104,C42)*F42*IF(D42="บอส",ตั้งค่า!$C$29,1),0) -> 226640 | I42: =ROUND(INDEX(เลเวล!$F$5:$F$104,C42)*IF(D42="บอส",ตั้งค่า!$C$32,1),0) -> 150 | J42: =ROUND(INDEX(เลเวล!$I$5:$I$104,C42)*IF(D42="บอส",ตั้งค่า!$C$31,1),0) -> 993 | K42: =ROUND(INDEX(เลเวล!$M$5:$M$104,C42)*G42*IF(D42="บอส",ตั้งค่า!$C$30,1),0) -> 58250 | L42: =ROUND(INDEX(เลเวล!$N$5:$N$104,C42)*IF(D42="บอส",ตั้งค่า!$C$33,1),0) -> 18640 | M42: =ROUND(INDEX(เลเวล!$O$5:$O$104,C42)*IF(D42="บอส",ตั้งค่า!$C$33,1),0) -> 27960 | N42: =ROUNDUP(H42/INDEX(เลเวล!$G$5:$G$104,C42),0) -> 160 | O42: บอสสุดท้าย
A43: ปูแดง | B43: ทุ่งนาริมคลอง | C43: 3 | D43: ปกติ | E43: ไม่ตีก่อน | F43: 1.3 | G43: 1.15 | H43: =ROUND(INDEX(เลเวล!$H$5:$H$104,C43)*F43*IF(D43="บอส",ตั้งค่า!$C$29,1),0) -> 81 | I43: =ROUND(INDEX(เลเวล!$F$5:$F$104,C43)*IF(D43="บอส",ตั้งค่า!$C$32,1),0) -> 1 | J43: =ROUND(INDEX(เลเวล!$I$5:$I$104,C43)*IF(D43="บอส",ตั้งค่า!$C$31,1),0) -> 10 | K43: =ROUND(INDEX(เลเวล!$M$5:$M$104,C43)*G43*IF(D43="บอส",ตั้งค่า!$C$30,1),0) -> 43 | L43: =ROUND(INDEX(เลเวล!$N$5:$N$104,C43)*IF(D43="บอส",ตั้งค่า!$C$33,1),0) -> 15 | M43: =ROUND(INDEX(เลเวล!$O$5:$O$104,C43)*IF(D43="บอส",ตั้งค่า!$C$33,1),0) -> 22
